<?xml version="1.0" ?>
<robot name="six_dof_arm">

<!-- 색깔지정 -->
    <material name="black">
        <color rgba="0.0 0.0 0.0 1.0"/>
    </material>
    <material name="orange">
        <color rgba="1.0 0.423529411765 0.0392156862745 1.0"/>
    </material>

<!-- link 시작 -->
<!-- 어깨 -->
    <link name="base"/>

    <joint name="fixed" type="fixed">
        <parent link="base"/>
        <child link="link1"/>
    </joint>

    <link name="link1">
        <collision>
            <origin rpy="0 0 0" xyz="0 0 0.315"/>
            <geometry>
                <box size="0.04 0.04 0.63"/>
            </geometry>
        </collision>
        <visual>
            <origin rpy="0 0 0" xyz="0 0 0.315"/>
            <geometry>
                <box size="0.04 0.04 0.63"/>
            </geometry>
            <material name="black"/>
        </visual>
        <inertial>
            <origin rpy="0 0 0" xyz="0 0 1.0"/>
            <mass value="1"/>
            <inertia ixx="1.0" ixy="0.0" ixz="0.0" iyy="1.0" iyz="0.0" izz="1.0"/>
        </inertial>
    </link>

    <joint name="joint1" type="revolute">
        <parent link="link1"/>
        <child link="link2"/>
        <origin rpy="0 0 0" xyz="0 0.03 0.625"/>
        <axis xyz="0 1 0"/>
        <limit effort="30" lower="-3.14" upper="3.14" velocity="1.571"/>
    </joint>

    <link name="link2">
        <collision>
            <origin rpy="0 0 0" xyz="0 0 0"/>
            <geometry>
                <box size="0.02 0.02 0.02"/>
            </geometry>
        </collision>
        <visual>
            <origin rpy="0 0 0" xyz="0 0 0"/>
            <geometry>
                <box size="0.02 0.02 0.02"/>
            </geometry>
            <material name="orange"/>
        </visual>
        <inertial>
            <origin rpy="0 0 0" xyz="0 0 0"/>
            <mass value="1"/>
            <inertia ixx="1.0" ixy="0.0" ixz="0.0" iyy="1.0" iyz="0.0" izz="1.0"/>
        </inertial>
    </link>

    <joint name="joint2" type="revolute">
        <parent link="link2"/>
        <child link="link3"/>
        <origin rpy="0 0 0" xyz="0 0.02 0"/>
        <axis xyz="1 0 0"/>
        <limit effort="30" lower="-0.5" upper="3.14" velocity="1.571"/>
    </joint>

    <link name="link3">
        <collision>
            <origin rpy="0 0 0" xyz="0 0 0"/>
            <geometry>
                <box size="0.02 0.02 0.02"/>
            </geometry>
        </collision>
        <visual>
            <origin rpy="0 0 0" xyz="0 0 0"/>
            <geometry>
                <box size="0.02 0.02 0.02"/>
            </geometry>
            <material name="black"/>
        </visual>
        <inertial>
            <origin rpy="0 0 0" xyz="0 0 0"/>
            <mass value="1"/>
            <inertia ixx="1.0" ixy="0.0" ixz="0.0" iyy="1.0" iyz="0.0" izz="1.0"/>
        </inertial>
    </link> 
    
    <joint name="joint3" type="revolute">
        <parent link="link3"/>
        <child link="link4"/>
        <origin rpy="0 0 0" xyz="0 0 -0.01"/>
        <axis xyz="0 0 1"/>
        <limit effort="30" lower="-3.14" upper="3.14" velocity="1.571"/>
    </joint>

    <link name="link4">
        <collision>
            <origin rpy="0 0 0" xyz="0 0 -0.125"/>
            <geometry>
                <box size="0.02 0.02 0.25"/>
            </geometry>
        </collision>
        <visual>
            <origin rpy="0 0 0" xyz="0 0 -0.125"/>
            <geometry>
                <box size="0.02 0.02 0.25"/>
            </geometry>
            <material name="orange"/>
        </visual>
        <inertial>
            <origin rpy="0 0 0" xyz="0 0 -0.125"/>
            <mass value="1"/>
            <inertia ixx="1.0" ixy="0.0" ixz="0.0" iyy="1.0" iyz="0.0" izz="1.0"/>
        </inertial>
    </link> 
<!-- 팔꿈치 -->
    <joint name="joint4" type="revolute">
        <parent link="link4"/>
        <child link="link5"/>
        <origin rpy="0 0 0" xyz="0 0 -0.25"/>
        <axis xyz="1 0 0"/>
        <limit effort="30" lower="-2.5" upper="0" velocity="1.571"/>
    </joint>

    <link name="link5">
        <collision>
            <origin rpy="0 0 0" xyz="0 0 -0.1"/>
            <geometry>
                <box size="0.02 0.02 0.2"/>
            </geometry>
        </collision>
        <visual>
            <origin rpy="0 0 0" xyz="0 0 -0.1"/>
            <geometry>
                <box size="0.02 0.02 0.2"/>
            </geometry>
            <material name="black"/>
        </visual>
        <inertial>
            <origin rpy="0 0 0" xyz="0 0 -0.1"/>
            <mass value="1"/>
            <inertia ixx="1.0" ixy="0.0" ixz="0.0" iyy="1.0" iyz="0.0" izz="1.0"/>
        </inertial>
    </link> 

<!-- 손목 -->

<joint name="joint5" type="revolute">
        <parent link="link5"/>
        <child link="link6"/>
        <origin rpy="0 0 0" xyz="0 0 -0.2"/>
        <axis xyz="0 0 1"/>
        <limit effort="30" lower="-3.14" upper="3.14" velocity="1.571"/>
    </joint>

    <link name="link6">
        <collision>
            <origin rpy="0 0 0" xyz="0 0 -0.01"/>
            <geometry>
                <box size="0.02 0.02 0.02"/>
            </geometry>
        </collision>
        <visual>
            <origin rpy="0 0 0" xyz="0 0 -0.01"/>
            <geometry>
                <box size="0.02 0.02 0.02"/>
            </geometry>
            <material name="orange"/>
        </visual>
        <inertial>
            <origin rpy="0 0 0" xyz="0 0 -0.01"/>
            <mass value="1"/>
            <inertia ixx="1.0" ixy="0.0" ixz="0.0" iyy="1.0" iyz="0.0" izz="1.0"/>
        </inertial>
    </link> 

    <joint name="joint6" type="revolute">
        <parent link="link6"/>
        <child link="link7"/>
        <origin rpy="0 0 0" xyz="0 0 -0.02"/>
        <axis xyz="1 0 0"/>
        <limit effort="30" lower="-2" upper="2" velocity="1.571"/>
    </joint>

    <link name="link7">
        <collision>
            <origin rpy="0 0 0" xyz="0 0 -0.05"/>
            <geometry>
                <box size="0.02 0.02 0.1"/>
            </geometry>
        </collision>
        <visual>
            <origin rpy="0 0 0" xyz="0 0 -0.05"/>
            <geometry>
                <box size="0.02 0.02 0.1"/>
            </geometry>
            <material name="black"/>
        </visual>
        <inertial>
            <origin rpy="0 0 0" xyz="0 0 -0.05"/>
            <mass value="1"/>
            <inertia ixx="1.0" ixy="0.0" ixz="0.0" iyy="1.0" iyz="0.0" izz="1.0"/>
        </inertial>
    </link> 

</robot>